Workbook

Sheet COVER
I1: (For Office use Only)
A6: Government of Maharashtra
A7: Water Resources Department
A8: Vidarbha Irrigation Development Corporation, Nagpur
A9: Chief Engineer, Water Resources Department, Amravati
A10: Superintending Engineer, Jigaon Project Irrigation Circle, Shegaon
A19: J I G A O N P R O J E C T
A20: Tq. Nandura Dist. Buldhana
A22: =+#REF! -> #REF!
A24: Name of Farmer | C24: :- | D24: =+FS!C13 -> Eknath pandurang tharkar
A25: Gat No. | C25: :- | D25: =+FS!C15 -> 193 | F25: =[1]FS!G13 -> L.A. Case No: 03/2021-22
A26: Amount | C26: :- | D26: =+FS!G15 -> 823876 | E26: /-
A28: Executive Engineer, Jigaon Rehabilitition Division, Khamgaon
A29: Subdivisional Engineer, Jigaon Rehabilitation Sub Div. No.1, Shegaon

Sheet FS
H1: P.W.D.229 E
E2: ESTIMATE
A3: DIVISION: JIGAON REHABILITATION DIVISION, KHAMGAON
A4: Sanctioned Estimate No.
A5: FUND HEAD : | D5: Vidarbha Irrigation Development Corporation , Nagpur.
A6: MAJOR HEAD : | D6: 4701 Capital Outlay on Major & Medium Irrigation Project.
A7: MINOR HEAD : | D7: 190-Investment in Public Sectors& other Undertakings.
D8: (Four) Capital Grants to V.I.D.Corporation.
A9: SERVICE HEAD : | D9: Jigaon Project.
A10: DEPARTMENTAL HEAD : | D10: I- HEAD WORKS
D11: B-LAND ACQUISITION
A12: Estimate framed in the Office of The Executive Engineer, Jigaon Rehabilitition Division, Khamgaon for the probable expenditure that will be incurred in ESTIMATE FOR VALUATION OF HOUSES/ PROPERTIES IN VILLAGE SURROUNDING OF Bondgaon TAL: Shegaon, DIST: BULDHANA, COMING UNDER SUBMERGENCE OF JIGAON PROJECT.
A13: Name of Owner :- | C13: =+DEP!C5 -> Eknath pandurang tharkar | G13: =[2]DEP!F6 -> L.A. Case No: 03/2021-22
A14: Village : | C14: Bondgaon
A15: Gut No. : | C15: =+DEP!C6 -> 193 | F15: Estimated Cost Rs. | G15: =+DEP!D24 -> 823876 | H15: /-
A17: Administratively approved under No................Date...............
A19: Technically sanctioned under No...................Date...............
A21: Estimate prepared by (Junior Engineer) And Checked by
H22: JE/AE-2
A23: Shri.. ………………….
A24: ( call or authority )
A25: General Description.
A26: The section-11 (as per LARRR Act 2013) for the L.A.Case 03/2021-22 of Village Sorrounding of Village Bhon Ta. Sangrampur Dist.Buldhana is published in Govt. Gazette on 30.06.2022. Hence, the PWD SSR 2021-22, WRD CSR 2022-23, M.J.P. S.S.R. 2021-22 & GSDA CSR 2021-22 is used for preparing the estimate of valuation of affected Properties.
C29: (A. R. Rathod) | G29: (S. D. Hase)
C30: Sub Divisional Engineer. | G30: Executive Engineer,
C31: Jigaon Rehab. Sub Div. No. 1 | G31: Jigaon Rehabilitation Division
C32: Shegaon | G32: Khamgaon

Sheet DEP
A1: JIGAON PROJECT
A2: Tal:- Nandura Dist :- Buldana
A3: =[2]ABSTRACT!A3 -> Name of Work:- Valuation of Properties on the Land of Village:Bhon (Tal: Sangrampur, Dist: Buldana)
A4: VALUATION BY DEPRECIATION
A5: Name of owner :- | C5: =+ABSTRACT!C4 -> Eknath pandurang tharkar
A6: Gut No.:- | C6: =+ABSTRACT!C5 -> 193 | F6: =+MS!J6 -> LA No. | G6: =+MS!L6 -> 01/2022-23
A7: Village | C7: =+FS!C14 -> Bondgaon
A8: CONSTRUCTION DETAILS
A9: 1) Type of structures | C9: Block masonary+ wooden plank
A10: 2) Total life of structure | C10: 10
A11: 3) Present Estimated cost Rs. | D11: =+ABSTRACT!G25 -> 1073836
A12: DEPRECIATION
A13: 1) Year of construction :- | D13: 2023
A14: 2) Present life | D14: =2026-D13 -> 3
A15: 3) Future life | D15: =C10-D14 -> 7
A16: 4) Y.P. for future life @ 7% | D16: =VLOOKUP(D15,YP!$A$2:B101,2,0) -> 5.389 | F16: (Ref PWD hand book Ch.37
A17: 5) Y.P. for Total life @ 7% | D17: =VLOOKUP(C10,YP!$A$2:B101,2,0) -> 7.024 | F17: vol-II Page No 34 & 35 )
A18: FORMULA
A19: Depreciated Value = Present Value X | E19: Y.P. for future life
E20: Y.P. for Total life
C22: = | D22: =+D11 -> 1073836 | E22: x | F22: =D16 -> 5.389
F23: =D17 -> 7.024
C24: =Rs: | D24: =ROUND(D22*F22/F23,0) -> 823876
B26: Prepared By :
F28: (A. R. Rathod)
B29: =[2]ABSTRACT!B36 -> (V.B.Nagose ) | F29: Sub Divisional Engineer.
B30: =[2]ABSTRACT!B37 -> JE | F30: Jigaon Rehab. Sub Div. No. 1
F31: Shegaon
B34: Checked By :
F35: (S. D. Hase)
F36: Executive Engineer,
B37: =[2]ABSTRACT!B42 -> JE/AE-2 | F37: Jigaon Rehabilitation Division
F38: Khamgaon

Sheet ABSTRACT
A1: JIGAON PROJECT
A2: Tal : Nandura Dist: Buldhana
A3: =+MS!A3 -> Name of Work:- Valuation of Properties on the Land of Village:Bondgaon (Tal: Shegaon, Dist: Buldana)
A4: Name | C4: =+MS!D4 -> Eknath pandurang tharkar
A5: Gut No :- | C5: =+MS!D5 -> 193 | D5: =[2]RA!A6 -> L.A. Case No: 03/2021-22
A6: Village:- | C6: =+DEP!C7 -> Bondgaon
A8: ABSTRACT SHEET
A10: Sr.No | B10: QTY | C10: DESCRIPTION OF ITEM | D10: RATE | E10: UNIT | F10: Ref. Of RA Item No | G10: AMOUNT
A11: 1 | B11: =ROUND(VLOOKUP(A11,MS!$B$9:O153,13,0),2) -> 10.33 | C11: =VLOOKUP(F11,RA!$A$2:D141,2,0) -> Excavation for foundation in earth, soil of all types, sand, gravel and soft murum, including removing the excavated material up to a distance of 50 m. beyond the building area and stacking and spreading as directed, dewatering, preparing the bed for the foundation and necessary back filling, ramming, watering including shoring and strutting etc. complete. (Lift upto 1.5 m.) By mechanical means | D11: =VLOOKUP(F11,RA!$A$2:D141,3,0) -> 202.85 | E11: =VLOOKUP(F11,RA!$A$2:D141,4,0) -> Cum | F11: =VLOOKUP(A11,MS!$B$9:O153,2,0) -> 1 | G11: =ROUND(D11*B11,0) -> 2095
A12: 2 | B12: =ROUND(VLOOKUP(A12,MS!$B$9:O154,13,0),2) -> 2.58 | C12: =VLOOKUP(F12,RA!$A$2:D142,2,0) -> Providing dry/ trap/ granite/ quartzite/ gneiss rubble stone soling 15 cm to 20 cm thick including hand packing and compacting etc. complete. | D12: =VLOOKUP(F12,RA!$A$2:D142,3,0) -> 2130.4 | E12: =VLOOKUP(F12,RA!$A$2:D142,4,0) -> Cum | F12: =VLOOKUP(A12,MS!$B$9:O154,2,0) -> 4 | G12: =ROUND(D12*B12,0) -> 5496
A13: 3 | B13: =ROUND(VLOOKUP(A13,MS!$B$9:O160,13,0),2) -> 7.75 | C13: =VLOOKUP(F13,RA!$A$2:D143,2,0) -> Providing and laying Cast in situ/Ready Mix cement concrete M-20 of trap / granite /quartzite/ gneiss metal for R.C.C. beams and lintels as per detailed designs and drawings or as directed including centering, formwork, cover blocks, laying/pumping, compactionand roughening the surface if special finish is to be provided and curing etc. complete. (Excluding reinforcement and structural steel). with fully automatic micro processor based PLC with SCADA enabled reversible Drum Type mixer/ concrete Batch mix plant (Pan mixer) etc. complete. With fine aggregate (crushed sand VSI grade) | D13: =VLOOKUP(F13,RA!$A$2:D143,3,0) -> 12639.7 | E13: =VLOOKUP(F13,RA!$A$2:D143,4,0) -> Cum | F13: =VLOOKUP(A13,MS!$B$9:O160,2,0) -> 21 | G13: =ROUND(D13*B13,0) -> 97958
A14: 4 | B14: =ROUND(VLOOKUP(A14,MS!$B$9:O161,13,0),2) -> 4.29 | C14: =VLOOKUP(F14,RA!$A$2:D144,2,0) -> Providing and fixing in position TMT - FE - 500 bar reinforcement of various diameters for R.C.C. pile caps,footings, foundations, slabs, beams columns, canopies,staircase, newels, chajjas, lintels pardis, copings, fins,arches etc. as per detailed designs, drawings and schedules. including cutting, bending, hooking the bars,binding with wires or tack welding and supporting as required complete as directed. | D14: =VLOOKUP(F14,RA!$A$2:D144,3,0) -> 7514.2 | E14: =VLOOKUP(F14,RA!$A$2:D144,4,0) -> Qtl | F14: =VLOOKUP(A14,MS!$B$9:O161,2,0) -> 121 | G14: =ROUND(D14*B14,0) -> 32236
A15: 5 | B15: =ROUND(VLOOKUP(A15,MS!$B$9:O169,13,0),2) -> 28.37 | C15: =VLOOKUP(F15,RA!$A$2:D145,2,0) -> Providing Autoclaved Aerated Concrete Block masonary of conforming to IS:2185 (Part3) -1984 in extra fine jointing mortar of fix o block of UltraTechor equivalent in superstructure including striking joints ,raking out joints and scaffolding etc. Complete. (The test shall be carried out conforming to IS:6441 (Part I) - 1972) | D15: =VLOOKUP(F15,RA!$A$2:D145,3,0) -> 7152.1 | E15: =VLOOKUP(F15,RA!$A$2:D145,4,0) -> Cum | F15: =VLOOKUP(A15,MS!$B$9:O169,2,0) -> 19.1 | G15: =ROUND(D15*B15,0) -> 202905
A16: 6 | B16: =ROUND(VLOOKUP(A16,MS!$B$9:O170,13,0),2) -> 0.84 | C16: =VLOOKUP(F16,RA!$A$2:D146,2,0) -> Providing and laying in situ/Ready Mix cement concrete M-20 of trap / granite /quartzite/ gneiss metal for R.C.C. work in foundations like raft, strip foundations, grillage and footings of R.C.C. columns and steel stanchions etc. including bailing out water, formwork, laying/pumping cover blocks, compaction and curing roughening the surface if special finish is to be provided (Excluding reinforcement and structural steel) etc.complete, with fully automatic micro processor based PLC with SCADA enabled reversible Drum Type mixer/ concrete Batch mix plant (Pan mixer) etc. complete. fine aggregate (crushed sand VSI grade) | D16: =VLOOKUP(F16,RA!$A$2:D146,3,0) -> 7578 | E16: =VLOOKUP(F16,RA!$A$2:D146,4,0) -> Cum | F16: =VLOOKUP(A16,MS!$B$9:O170,2,0) -> 6 | G16: =ROUND(D16*B16,0) -> 6366
A17: 7 | B17: =ROUND(VLOOKUP(A17,MS!$B$9:O171,13,0),2) -> 5.14 | C17: =VLOOKUP(F17,RA!$A$2:D147,2,0) -> Providing and fixing Jungle (hard) wood of approved species joist and girder in timber floor of single, double or frame type including scafolding if necessary and one primer coat etc. complete | D17: =VLOOKUP(F17,RA!$A$2:D147,3,0) -> 56662.35 | E17: =VLOOKUP(F17,RA!$A$2:D147,4,0) -> Cum. | F17: =VLOOKUP(A17,MS!$B$9:O171,2,0) -> 68 | G17: =ROUND(D17*B17,0) -> 291244
A18: 8 | B18: =ROUND(VLOOKUP(A18,MS!$B$9:O172,13,0),2) -> 168.93 | C18: =VLOOKUP(F18,RA!$A$2:D148,2,0) -> Providing and laying of Ceramic tiles 30x30cm etc complete as Directed | D18: =VLOOKUP(F18,RA!$A$2:D148,3,0) -> 507.1 | E18: =VLOOKUP(F18,RA!$A$2:D148,4,0) -> Sqm. | F18: =VLOOKUP(A18,MS!$B$9:O172,2,0) -> 112 | G18: =ROUND(D18*B18,0) -> 85664
A19: 9 | B19: =ROUND(VLOOKUP(A19,MS!$B$9:O173,13,0),2) -> 184.53 | C19: =VLOOKUP(F19,RA!$A$2:D149,2,0) -> Providing and fixing non teak wood plank ceiling 12 mm. Thick with planked on underside longuled and grooved including scaffolding, fixtures with oiling and two coats of varnishing etc. conplete. (Excluding battens and joists) as directed. | D19: =VLOOKUP(F19,RA!$A$2:D149,3,0) -> 1166 | E19: =VLOOKUP(F19,RA!$A$2:D149,4,0) -> Sqm | F19: =VLOOKUP(A19,MS!$B$9:O173,2,0) -> 98 | G19: =ROUND(D19*B19,0) -> 215162
A20: 10 | B20: =ROUND(VLOOKUP(A20,MS!$B$9:O174,13,0),2) -> 107.76 | C20: =VLOOKUP(F20,RA!$A$2:D150,2,0) -> Providing sand faced plaster externally in cement mortar using approved screened sand, in all positions including base coat of 15 mm thick in cement mortar 1:4 using waterproofing compound at 1 kg per cement bag curing the same for not less than 2 days and keeping the surface of the base coat rough to receive the sand faced treatment 6 to 8 mm thick in cement mortar 1:4 finishing the surface by taking out grains and curing for fourteen days scaffolding etc.complete | D20: =VLOOKUP(F20,RA!$A$2:D150,3,0) -> 637.25 | E20: =VLOOKUP(F20,RA!$A$2:D150,4,0) -> Sqm. | F20: =VLOOKUP(A20,MS!$B$9:O174,2,0) -> 30 | G20: =ROUND(D20*B20,0) -> 68670
A21: 11 | B21: =ROUND(VLOOKUP(A21,MS!$B$9:O175,13,0),2) -> 95.27 | C21: =VLOOKUP(F21,RA!$A$2:D151,2,0) -> Providing internal cement plaster 6 mm thick in single coat in cement mortar 1:4 without neeru finish to concrete or brick surfaces, in all positions including scaffolding and curing etc. complete. | D21: =VLOOKUP(F21,RA!$A$2:D151,3,0) -> 201.4 | E21: =VLOOKUP(F21,RA!$A$2:D151,4,0) -> Sqm. | F21: =VLOOKUP(A21,MS!$B$9:O175,2,0) -> 29 | G21: =ROUND(D21*B21,0) -> 19187
A22: 12 | B22: =ROUND(VLOOKUP(A22,MS!$B$9:O176,13,0),2) -> 15.74 | C22: =VLOOKUP(F22,RA!$A$2:D152,2,0) -> Providing and fixing Jungle wood door of frame 60 mm X 100 mm for second class door's and window with / without ventilator fan light and clear storey windows including chamfering / rounding rebating and hold fast finishing with one coat of primer etc. conplete. as directed. | D22: =VLOOKUP(F22,RA!$A$2:D152,3,0) -> 2976.7 | E22: =VLOOKUP(F22,RA!$A$2:D152,4,0) -> Sqm | F22: =VLOOKUP(A22,MS!$B$9:O176,2,0) -> 97 | G22: =ROUND(D22*B22,0) -> 46853
D24: Total Amount Rs. | G24: =SUM(G11:G23) -> 1073836
D25: Say Rs. | G25: =ROUNDUP(G24,2) -> 1073836
B26: Prepared By
E30: (A. R. Rathod)
E31: Sub Divisional Engineer.
B32: =[2]MS!A130 -> (V.B.Nagose ) | E32: Jigaon Rehab. Sub Div. No. 1
B33: =[2]MS!A131 -> JE | E33: Shegaon
B35: Checked By
E37: (S. D. Hase)
B38: =[2]MS!F131 -> JE/AE-2 | E38: Executive Engineer,
E39: Jigaon Rehabilitation Division
E40: Khamgaon

Sheet MS
A1: JIGAON PROJECT
A2: Tal : Nandura Dist: Buldana
A3: Name of Work:- Valuation of Properties on the Land of Village:Bondgaon (Tal: Shegaon, Dist: Buldana)
A4: Name of Owner :- | D4: Eknath pandurang tharkar
A5: Gut No. :- | D5: 193
A6: Village :- | D6: Bondgaon | J6: LA No. | K6: - | L6: 01/2022-23
A7: MEASUREMENT SHEET
B8: Sr.No | C8: Item No | D8: Description of Item
B9: 1 | C9: 1 | D9: =VLOOKUP(C9,RA!$A$2:D141,2,0) -> Excavation for foundation in earth, soil of all types, sand, gravel and soft murum, including removing the excavated material up to a distance of 50 m. beyond the building area and stacking and spreading as directed, dewatering, preparing the bed for the foundation and necessary back filling, ramming, watering including shoring and strutting etc. complete. (Lift upto 1.5 m.) By mechanical means | N9: =+L16 -> 10.33 | P9: =3.6+3.6+3.5+3.8+5*0.15 -> 15.25
D10: EXCAVATION
D11: Nos | E11: x | F11: L (m) | G11: x | H11: B (m) | I11: x | J11: D/H (m) | K11: = | L11: Qty | M11: Unit
A12: LW | D12: 3 | E12: x | F12: =3.6+3.6+3.5+3.8+0.15*5+0.1 -> 15.35 | G12: x | H12: 0.25 | I12: x | J12: 0.4 | K12: = | L12: =PRODUCT(D12:J12) -> 4.605 | M12: Cum
A13: SW | D13: 5 | E13: x | F13: =5.9-0.1 -> 5.8 | G13: x | H13: 0.25 | I13: x | J13: 0.4 | K13: = | L13: =PRODUCT(D13:J13) -> 2.9 | M13: Cum
A14: SW | D14: 5 | E14: x | F14: =5.75-0.1 -> 5.65 | G14: x | H14: 0.25 | I14: x | J14: 0.4 | K14: = | L14: =PRODUCT(D14:J14) -> 2.825 | M14: Cum | T14: =3.6+3.6+3.6+3.5+0.15*3+0.15+0.25 -> 15.15
J16: Total Qty. | K16: = | L16: =SUM(L12:L15) -> 10.33 | M16: Cum
B18: =+B9+1 -> 2 | C18: 4 | D18: =VLOOKUP(C18,RA!$A$2:D149,2,0) -> Providing dry/ trap/ granite/ quartzite/ gneiss rubble stone soling 15 cm to 20 cm thick including hand packing and compacting etc. complete. | N18: =+L25 -> 2.5825
D19: SOLING
D20: Nos | E20: x | F20: L (m) | G20: x | H20: B (m) | I20: x | J20: D/H (m) | K20: = | L20: Qty | M20: Unit
A21: =+A12 -> LW | D21: =+D12 -> 3 | E21: x | F21: =+F12 -> 15.35 | G21: x | H21: 0.25 | I21: x | J21: 0.1 | K21: = | L21: =PRODUCT(D21:J21) -> 1.15125 | M21: Cum
A22: =+A13 -> SW | D22: =+D13 -> 5 | E22: x | F22: =+F13 -> 5.8 | G22: x | H22: 0.25 | I22: x | J22: 0.1 | K22: = | L22: =PRODUCT(D22:J22) -> 0.725 | M22: Cum
A23: =+A14 -> SW | D23: =+D14 -> 5 | E23: x | F23: =+F14 -> 5.65 | G23: x | H23: 0.25 | I23: x | J23: 0.1 | K23: = | L23: =PRODUCT(D23:J23) -> 0.70625 | M23: Cum
J25: Total Qty. | K25: = | L25: =SUM(L21:L24) -> 2.5825 | M25: Cum
B27: =+B18+1 -> 3 | C27: 21 | D27: =VLOOKUP(C27,RA!$A$2:D157,2,0) -> Providing and laying Cast in situ/Ready Mix cement concrete M-20 of trap / granite /quartzite/ gneiss metal for R.C.C. beams and lintels as per detailed designs and drawings or as directed including centering, formwork, cover blocks, laying/pumping, compactionand roughening the surface if special finish is to be provided and curing etc. complete. (Excluding reinforcement and structural steel). with fully automatic micro processor based PLC with SCADA enabled reversible Drum Type mixer/ concrete Batch mix plant (Pan mixer) etc. complete. With fine aggregate (crushed sand VSI grade) | N27: =+L34 -> 7.7475
D28: RCC GROUND BEAM
D29: Nos | E29: x | F29: L (m) | G29: x | H29: B (m) | I29: x | J29: D/H (m) | K29: = | L29: Qty | M29: Unit
A30: =+A21 -> LW | D30: =+D21 -> 3 | E30: x | F30: =+F21 -> 15.35 | G30: x | H30: 0.25 | I30: x | J30: 0.3 | K30: = | L30: =PRODUCT(D30:J30) -> 3.45375 | M30: Cum
A31: =+A22 -> SW | D31: =+D22 -> 5 | E31: x | F31: =+F22 -> 5.8 | G31: x | H31: 0.25 | I31: x | J31: 0.3 | K31: = | L31: =PRODUCT(D31:J31) -> 2.175 | M31: Cum
A32: =+A23 -> SW | D32: =+D23 -> 5 | E32: x | F32: =+F23 -> 5.65 | G32: x | H32: 0.25 | I32: x | J32: 0.3 | K32: = | L32: =PRODUCT(D32:J32) -> 2.11875 | M32: Cum
J34: Total Qty. | K34: = | L34: =SUM(L30:L33) -> 7.7475 | M34: Cum
B36: =+B27+1 -> 4 | C36: 121 | D36: =VLOOKUP(C36,RA!$A$2:D165,2,0) -> Providing and fixing in position TMT - FE - 500 bar reinforcement of various diameters for R.C.C. pile caps,footings, foundations, slabs, beams columns, canopies,staircase, newels, chajjas, lintels pardis, copings, fins,arches etc. as per detailed designs, drawings and schedules. including cutting, bending, hooking the bars,binding with wires or tack welding and supporting as required complete as directed. | N36: =+L41 -> 4.29
D37: STEEL | K37: = | L37: Qty | M37: Unit
A38: =+D28 -> RCC GROUND BEAM | F38: =+L34 -> 7.7475 | G38: x | H38: 50 | I38: kg/M3 | K38: = | L38: =ROUND(PRODUCT(E38:J38)/100,2) -> 3.87 | M38: Qtl
A39: =+D56 -> RCC COLUMNS | F39: =+L60 -> 0.842175 | G39: x | H39: 50 | I39: kg/M3 | K39: = | L39: =ROUND(PRODUCT(E39:J39)/100,2) -> 0.42 | M39: Qtl
K41: Total Quantity | L41: =SUM(L38:L40) -> 4.29 | M41: Qtl
B43: =+B36+1 -> 5 | C43: 19.1 | D43: =VLOOKUP(C43,RA!$A$2:D165,2,0) -> Providing Autoclaved Aerated Concrete Block masonary of conforming to IS:2185 (Part3) -1984 in extra fine jointing mortar of fix o block of UltraTechor equivalent in superstructure including striking joints ,raking out joints and scaffolding etc. Complete. (The test shall be carried out conforming to IS:6441 (Part I) - 1972) | N43: =+L53 -> 28.371
D44: SUPERSTRUCTURE MASONRY - BLOCK WALL
D45: Nos | E45: x | F45: L (m) | G45: x | H45: B (m) | I45: x | J45: D/H (m) | K45: = | L45: Qty | M45: Unit
A46: =+A30 -> LW | D46: =+D30 -> 3 | E46: x | F46: =+F30-0.05-0.05 -> 15.25 | G46: x | H46: 0.15 | I46: x | J46: 1.97 | K46: = | L46: =PRODUCT(D46:J46) -> 13.519125 | M46: Cum | R46: =3.6*3+3.5+0.15*5 -> 15.05
A47: =+A31 -> SW | D47: =+D31 -> 5 | E47: x | F47: =+F31+0.05+0.05 -> 5.9 | G47: x | H47: 0.15 | I47: x | J47: 1.97 | K47: = | L47: =PRODUCT(D47:J47) -> 8.71725 | M47: Cum
A48: =+A32 -> SW | D48: =+D32 -> 5 | E48: x | F48: =+F32+0.05+0.05 -> 5.75 | G48: x | H48: 0.15 | I48: x | J48: 1.97 | K48: = | L48: =PRODUCT(D48:J48) -> 8.495625 | M48: Cum
...

Sheet RA
A1: item No | B1: description | C1: rate | D1: unit
A2: 1 | B2: Excavation for foundation in earth, soil of all types, sand, gravel and soft murum, including removing the excavated material up to a distance of 50 m. beyond the building area and stacking and spreading as directed, dewatering, preparing the bed for the foundation and necessary back filling, ramming, watering including shoring and strutting etc. complete. (Lift upto 1.5 m.) By mechanical means | C2: 202.85 | D2: Cum
A3: 2 | B3: Excavation for foundation in earth, soils of all types, sand,gravel and soft murum, including removing the excavated material upto a distance of 50 metres beyond the building area and stacking and spreading as directed, dewatering, preparing the bed for the foundation and necessary back filling, ramming, watering including shoring and strutting etc. complete. (Lift from 1.5m to 3.0m) By mechanical means | C3: 252.85 | D3: Cum
A4: 3 | B4: Excavation for foundation in hard murum including removing the excavated material upto distance of 50 metres beyond the building area and stacking and spreading as directed, dewatering, preparing the bed for the foundation and necessary back filling, ramming, watering including shoring and strutting etc. complete. (Lift upto 1.50 m) By mechanical means | C4: 222.45 | D4: Cum
A5: 4 | B5: Providing dry/ trap/ granite/ quartzite/ gneiss rubble stone soling 15 cm to 20 cm thick including hand packing and compacting etc. complete. | C5: 2130.4 | D5: Cum
A6: 5 | B6: Providing and laying Cast in situ/Ready Mix cement concrete in M-10 of trap/ granite/ quartzite/ gneiss metal for foundation and bedding including bailing out water, formwork, laying/pumping, compacting, roughening them if special finish is to be provided, finishing if required and curing complete, with fully automatic micro processor based PLC with SCADA enabled reversible Drum Type mixer/concrete Batch mix plant (Pan mixer) etc. complete. With fine aggregate (crushed sand VSI grade) | C6: 6335.75 | D6: Cum
A7: 6 | B7: Providing and laying in situ/Ready Mix cement concrete M-20 of trap / granite /quartzite/ gneiss metal for R.C.C. work in foundations like raft, strip foundations, grillage and footings of R.C.C. columns and steel stanchions etc. including bailing out water, formwork, laying/pumping cover blocks, compaction and curing roughening the surface if special finish is to be provided (Excluding reinforcement and structural steel) etc.complete, with fully automatic micro processor based PLC with SCADA enabled reversible Drum Type mixer/ concrete Batch mix plant (Pan mixer) etc. complete. fine aggregate (crushed sand VSI grade) | C7: 7578 | D7: Cum
A8: 7 | B8: Providing and constructing stone masonry in mud mortar in foundation and plinth including scaffolding, finishing etc. complete. A) Up to Plinth | C8: 1982.8 | D8: Cum
A9: 8 | B9: Providing and constructing U.C.R.masonry in lime 1:6 mortar in foundation and plinth including scaffolding, finishing etc. complete. | C9: 3017.35 | D9: Cum
A10: 9 | B10: Providing and constructing stone masonry in mud mortar in foundation and plinth including scaffolding, finishing etc. complete. B) Superstructure | C10: 2154.15 | D10: Cum
A11: 10 | B11: Providing uncoursed rubble masonry of trap / granite / quartzite / gneiss stones in cement mortar 1:6 in foundation and plinth of inner walls / in plinth of external walls including bailing out water manually , striking joints on un exposed faces and watering etc.complete. | C11: 5926.35 | D11: Cum
A12: 11 | B12: Providing coursed rubble masonry first sort of trap / granite / quartzite / gneiss stones in cement mortar 1:6 in superstructure including racking out joints on the inside when plastering is to be done, watering and scaffolding etc. complete. | C12: 14010.35 | D12: cum
A13: 12 | B13: Filling in plinth and floors with approved excavated material in 15cm. to 20cm. layers including watering and compacting etc. complete. | C13: 117.6 | D13: Cum
... A93: 89 | B93: Providing and fixing black kadappa stone as shelves 25mm. Thick machine polished, extending the polish upto 20 cm width on lowerside, rounding corners, laying in position jointing with bedding cement mortar 1:4 proportion curing etc etc. complete. | C93: 1228.8 | D93: Sqm
A94: 90 | B94: Providing and laying in trenches CPVC pipes of required diameter including necessary excavation, fittings. Refilling trenches etc. complete Including removing existing pipe line if necessary and conveying and stacking the same in PWD chowky or as directed etc. complete.
A95: 90.1 | B95: (i) 15 mm dia. | C95: 267.55 | D95: Rmt
A96: 90.2 | B96: (ii) 20 mm dia. | C96: 304.8 | D96: Rmt
A97: 90.3 | B97: (iii) 25 mm dia. | C97: 414.55 | D97: Rmt
A98: 91 | B98: Providing and fixing Orissa type white glazed earthenware 575mm watercloset pan including Strap with earthenware footrests, cast iron soil and vent pipe upto outside face of the wall 1:2:4 brick bat lime concrete bedding without flushing tank and its accessories etc. complete. | C98: 3926.85 | D98: No
A99: 92 | B99: Providing and erecting chain link fencing 1.6 M. height with G.I. chain link of size 50 x 50 mm, 8 gauge thick and fixed 75 mm above ground level on vertical M.S. Angles of 40 x 40 x 6 mm size, includind excavating pits for foundation and embedded in C.C. block of 1:4:8 mix of size 450 x 450 x 670 mm. at 1.75 M. c/c with iron bar 16mm dia as hold fast including welding link with angle frame at 30 cm c/c with nuts and bolts and horizontal M.S. Angles at top and bottom of 25 x 25 x 5 mm size and vertical M.S. flat 35 x 5 mm and 25 x 5 mm horizontal including cross support of 40 x 40 x 6 mm angles both side at every corner or bend embedded in concrete blocks of 1:4:8 of size 450 x 450 x 670 mm including 3 coats of oil painting etc. complete. | C99: 2265.3 | D99: Rmt.
A100: 93 | B100: Providing and applying boiled linseed oil in one coat, to the new wood work, including knotting, preparing the surface, scaffolding etc. Complete as directed. | C100: 26.45 | D100: Sqm
A101: 94 | B101: Providing and fixing stainless steel sink of size 600 x 510 x 200 mm incluidng coupling, outlet pipe, elbow and other necessary fitting, finishing etc. complete. | C101: 19502 | D101: No
A102: 95 | B102: Providing wiring for Fan \Light \Bell in 20 mm. HMS PVC Condut etc complete.
A103: 95.1 | B103: Point Wiring | C103: 489.06 | D103: No.
A104: 95.2 | B104: Individual Plug | C104: 554.4 | D104: No.
A105: 96 | B105: Providing and laying Polyethelene film 200 gauge for roof over any type of shed including labour etc. complete | C105: 27.15 | D105: /Sqm
A106: 97 | B106: Providing and fixing Jungle wood door of frame 60 mm X 100 mm for second class door's and window with / without ventilator fan light and clear storey windows including chamfering / rounding rebating and hold fast finishing with one coat of primer etc. conplete. as directed. | C106: 2976.7 | D106: Sqm
A107: 98 | B107: Providing and fixing non teak wood plank ceiling 12 mm. Thick with planked on underside longuled and grooved including scaffolding, fixtures with oiling and two coats of varnishing etc. conplete. (Excluding battens and joists) as directed. | C107: 1166 | D107: Sqm
A108: 99 | B108: Providing & fixing Country Teak Wood plank ceiling 12 mm. Thick with planked on underside, longuled and grooved includingscaffolding, fixtures with oiling and two coats of varnishing etc. complete. (excluding battens and joists) As directed by Engineer-In-Charge. | C108: 2088.2 | D108: Sqm
A109: 100 | B109: Providing & fixing wooden shelf of country teak wood plank 30 cm wide and 20 mm thick with wooden brackets of 50 mm x 50 mm without fillets including all fixtures with oil painting etc.complete. As directed by Engineer-In-Charge. | C109: 953.15 | D109: Sqm
A110: 101 | B110: Providing and fixing non teak doors/window II class fully pannelled without ventilators/fan light/iron bars including the frames of the sizes as per standard specification, Iron fixtures and fastenings and finishing the wood work with oil painting etc.complete. As directed by Engineer-In_x0002_Charge. | C110: 7296.35 | D110: Sqm
A111: 102 | B111: Providing and fixing Non Teak wood Dhaba Withought mud flooring etc. Complete | C111: 4864.2 | D111: Sqm
A112: 103 | B112: Providing and fixing teak wood dhaba Withought mud flooring etc. Complete | C112: 10734.25 | D112: Sqm
A113: 104 | B113: Providing and fixing fully glazed double leaf window shutter with openable fan light including Country cut teak wood 25mm thick style and rails with plain /obscured glass panels 5mm thick as per drawing or as directed by the Engineer in charge with stainless steel fixtures and fastening and finishing the woodwork with oil painting three coats etc. complete. | C113: 4707.9 | D113: Sqm
A114: 105 | B114: Providing and fixing frame with / without ventilator of size as specified with Country cut teak wood for doors and windows including chamfering, rounding, rebating, iron holdfast of size 300mm x 40mm x 5mm with oil painting, etc. Complete | C114: 176444.1 | D114: Cum
... A131: 122 | B131: Excavation for foundation / pipe trenches in earth, soils of all types, sand, gravel and soft murum, including removing the excavated material upto a distance of 50 metres and lifts as below, stacking and spreading as directed, manual dewatering, preparing the bed for foundation and excluding backfilling, etc. complete. | C131: 160.05 | D131: Cum
A132: 123 | B132: Providing and supplying in standard lengths ISI mark rigid unplasticised PVC pipes suitable for potable water with solvent cement joints including cost of couplers, as per IS specification no. 4985 / 1988 including all local and central taxes, transportation, freight charges, inspection charges, loading, unloading, conveyance to the departmental stores / site and stacking the same in closed shed duly protected from sun rays and rains including cost of jointing material i.e. solvent cement, etc. complete (selffit type to be jointed with cement solvent) a) Working pressure 4 Kg/Sq.cm
A133: 123.1 | B133: 63mm dia pipe | C133: 78.55 | D133: Rmt
A134: 123.2 | B134: 75mm dia pipe | C134: 111.55 | D134: Rmt
A135: 123.3 | B135: 90 mm dia pipe | C135: 155.2 | D135: Rmt
...

Sheet YP
A1: Y.P VALUES
A2: 1 | B2: 0.935
A3: 2 | B3: 1.808
A4: 3 | B4: 2.624
A5: 4 | B5: 3.387
A6: 5 | B6: 4.1
A7: 6 | B7: 4.767
A8: 7 | B8: 5.389
A9: 8 | B9: 5.971
A10: 9 | B10: 6.515
A11: 10 | B11: 7.024
A12: 11 | B12: 7.499
A13: 12 | B13: 7.943
... A93: 92 | B93: 14.257
A94: 93
A95: 94
A96: 95
A97: 96
A98: 97
A99: 98
A100: 99
A101: 100
